<?xml version="1.0"?>
<robot name="kugle" xmlns:xacro="http://www.ros.org/wiki/xacro">

	<!--
     1. Create model with URDF: http://wiki.ros.org/urdf/Tutorials/Create%20your%20own%20urdf%20file
     2. Add controllable joints: http://wiki.ros.org/urdf/Tutorials/Building%20a%20Movable%20Robot%20Model%20with%20URDF
     3. Physical properties: http://wiki.ros.org/urdf/Tutorials/Adding%20Physical%20and%20Collision%20Properties%20to%20a%20URDF%20Model or http://gazebosim.org/tutorials/?tut=ros_urdf
     4. Use Macros: http://wiki.ros.org/urdf/Tutorials/Using%20Xacro%20to%20Clean%20Up%20a%20URDF%20File
     5. Link to Gazebo: http://wiki.ros.org/urdf/Tutorials/Using%20a%20URDF%20in%20Gazebo
    -->

	<!-- Inspired from https://github.com/mindThomas/JetsonCar-Simulation/blob/master/jetsoncar_description/urdf/jetsoncar.xacro -->

	<xacro:include filename="$(find kugle_description)/urdf/parameters.xacro" />
	<xacro:include filename="$(find kugle_description)/urdf/physical.xacro" />
	<xacro:include filename="$(find kugle_description)/urdf/joints.xacro" />
	<xacro:include filename="$(find kugle_description)/urdf/materials.xacro" />

	<!-- Base link is at the contact point (hence ground level) -->
	<link name="contact_point"/>

	<link name="ball">
		<visual>
			<material name="black"/>
			<xacro:ball_geometry/>
		</visual>
	</link>

	<xacro:fixed_offset_joint parent="contact_point" child="ball" offset="0 0 ${ball_radius}"/>

	<link name="heading" />
	<joint name="yaw" type="continuous">
		<parent link="ball"/>
		<child link="heading"/>
		<origin xyz="0 0 0" rpy="0 0 0" />
		<axis xyz="0 0 1"/>
	</joint>

	<link name="base_link">
		<visual>
			<!--<material name="grey"/>
			<xacro:robot_geometry/>-->
			<origin xyz="0 0 -${ball_radius}" rpy="0 0 ${pi/2}" />
			<geometry>
				<mesh filename="package://kugle_description/models/kugle.dae" scale="1.0 1.0 1.0"/>
			</geometry>
		</visual>
	</link>
	<joint name="tilt" type="continuous">
		<parent link="heading"/>
		<child link="base_link"/>
		<origin xyz="0 0 0" rpy="0 0 0" />
		<axis xyz="1 1 0"/>
	</joint>

	<!-- Include sensors links -->
	<link name="sick_left_link" />
	<xacro:fixed_offset_joint_rpy parent="base_link" child="sick_left_link" offset="0 0.123 0.33757" rpy="0 0 ${pi/2}" />

	<link name="sick_right_link" />
	<xacro:fixed_offset_joint_rpy parent="base_link" child="sick_right_link" offset="0 -0.123 0.33757" rpy="0 0 -${pi/2}" />

	<!-- Add realsense camera link -->
	<link name="realsense_camera_link">
		<visual>
	            <origin rpy="0 0 0" xyz="0 0 0"/>
	            <geometry>
	                <mesh filename="package://kugle_description/models/realsense_camera/meshes/realsense.dae"/>
	            </geometry>
		</visual>
	</link>
	<xacro:fixed_offset_joint_rpy parent="base_link" child="realsense_camera_link" offset="0.05 0 1.11" rpy="0 0.25 0" />

</robot>
